[2024-08-29 00:17:33,443] {taskinstance.py:1159} INFO - Dependencies all met for <TaskInstance: TwitterDAG.twitter_datascience scheduled__2024-08-28T00:00:00+00:00 [queued]>
[2024-08-29 00:17:33,449] {taskinstance.py:1159} INFO - Dependencies all met for <TaskInstance: TwitterDAG.twitter_datascience scheduled__2024-08-28T00:00:00+00:00 [queued]>
[2024-08-29 00:17:33,450] {taskinstance.py:1356} INFO - 
--------------------------------------------------------------------------------
[2024-08-29 00:17:33,450] {taskinstance.py:1357} INFO - Starting attempt 1 of 1
[2024-08-29 00:17:33,450] {taskinstance.py:1358} INFO - 
--------------------------------------------------------------------------------
[2024-08-29 00:17:33,460] {taskinstance.py:1377} INFO - Executing <Task(TwitterOperator): twitter_datascience> on 2024-08-28 00:00:00+00:00
[2024-08-29 00:17:33,463] {standard_task_runner.py:52} INFO - Started process 44763 to run task
[2024-08-29 00:17:33,468] {standard_task_runner.py:79} INFO - Running: ['airflow', 'tasks', 'run', 'TwitterDAG', 'twitter_datascience', 'scheduled__2024-08-28T00:00:00+00:00', '--job-id', '34', '--raw', '--subdir', 'DAGS_FOLDER/twitter_dag.py', '--cfg-path', '/tmp/tmpb203e76_', '--error-file', '/tmp/tmpn7lacz8j']
[2024-08-29 00:17:33,469] {standard_task_runner.py:80} INFO - Job 34: Subtask twitter_datascience
[2024-08-29 00:17:33,514] {task_command.py:370} INFO - Running <TaskInstance: TwitterDAG.twitter_datascience scheduled__2024-08-28T00:00:00+00:00 [running]> on host kaiwangairflow
[2024-08-29 00:17:33,581] {taskinstance.py:1569} INFO - Exporting the following env vars:
AIRFLOW_CTX_DAG_OWNER=airflow
AIRFLOW_CTX_DAG_ID=TwitterDAG
AIRFLOW_CTX_TASK_ID=twitter_datascience
AIRFLOW_CTX_EXECUTION_DATE=2024-08-28T00:00:00+00:00
AIRFLOW_CTX_TRY_NUMBER=1
AIRFLOW_CTX_DAG_RUN_ID=scheduled__2024-08-28T00:00:00+00:00
[2024-08-29 00:17:33,591] {taskinstance.py:1889} ERROR - Task failed with exception
Traceback (most recent call last):
  File "/home/kai/Documents/PROJETOS/twitter_extractor_airflow/airflow_twitter/operators/twitter_operator.py", line 33, in execute
    for pg in TwitterHook(end_time, start_time, query).run():
  File "/home/kai/Documents/PROJETOS/twitter_extractor_airflow/airflow_twitter/hook/twitter_hook.py", line 58, in run
    session = self.get_conn()
  File "/home/kai/Documents/PROJETOS/twitter_extractor_airflow/venv/lib/python3.9/site-packages/airflow/providers/http/hooks/http.py", line 68, in get_conn
    conn = self.get_connection(self.http_conn_id)
  File "/home/kai/Documents/PROJETOS/twitter_extractor_airflow/venv/lib/python3.9/site-packages/airflow/hooks/base.py", line 67, in get_connection
    conn = Connection.get_connection_from_secrets(conn_id)
  File "/home/kai/Documents/PROJETOS/twitter_extractor_airflow/venv/lib/python3.9/site-packages/airflow/models/connection.py", line 430, in get_connection_from_secrets
    raise AirflowNotFoundException(f"The conn_id `{conn_id}` isn't defined")
airflow.exceptions.AirflowNotFoundException: The conn_id `twitter_connection_default` isn't defined
[2024-08-29 00:17:33,594] {taskinstance.py:1395} INFO - Marking task as FAILED. dag_id=TwitterDAG, task_id=twitter_datascience, execution_date=20240828T000000, start_date=20240829T031733, end_date=20240829T031733
[2024-08-29 00:17:33,604] {standard_task_runner.py:92} ERROR - Failed to execute job 34 for task twitter_datascience (The conn_id `twitter_connection_default` isn't defined; 44763)
[2024-08-29 00:17:33,647] {local_task_job.py:156} INFO - Task exited with return code 1
[2024-08-29 00:17:33,661] {local_task_job.py:273} INFO - 0 downstream tasks scheduled from follow-on schedule check
[2024-08-29 00:27:31,386] {taskinstance.py:1159} INFO - Dependencies all met for <TaskInstance: TwitterDAG.twitter_datascience scheduled__2024-08-28T00:00:00+00:00 [queued]>
[2024-08-29 00:27:31,392] {taskinstance.py:1159} INFO - Dependencies all met for <TaskInstance: TwitterDAG.twitter_datascience scheduled__2024-08-28T00:00:00+00:00 [queued]>
[2024-08-29 00:27:31,392] {taskinstance.py:1356} INFO - 
--------------------------------------------------------------------------------
[2024-08-29 00:27:31,392] {taskinstance.py:1357} INFO - Starting attempt 1 of 1
[2024-08-29 00:27:31,392] {taskinstance.py:1358} INFO - 
--------------------------------------------------------------------------------
[2024-08-29 00:27:31,404] {taskinstance.py:1377} INFO - Executing <Task(TwitterOperator): twitter_datascience> on 2024-08-28 00:00:00+00:00
[2024-08-29 00:27:31,406] {standard_task_runner.py:52} INFO - Started process 48418 to run task
[2024-08-29 00:27:31,412] {standard_task_runner.py:79} INFO - Running: ['airflow', 'tasks', 'run', 'TwitterDAG', 'twitter_datascience', 'scheduled__2024-08-28T00:00:00+00:00', '--job-id', '44', '--raw', '--subdir', 'DAGS_FOLDER/twitter_dag.py', '--cfg-path', '/tmp/tmp9wux7wos', '--error-file', '/tmp/tmpichkl5cd']
[2024-08-29 00:27:31,413] {standard_task_runner.py:80} INFO - Job 44: Subtask twitter_datascience
[2024-08-29 00:27:31,460] {task_command.py:370} INFO - Running <TaskInstance: TwitterDAG.twitter_datascience scheduled__2024-08-28T00:00:00+00:00 [running]> on host kaiwangairflow
[2024-08-29 00:27:31,504] {taskinstance.py:1569} INFO - Exporting the following env vars:
AIRFLOW_CTX_DAG_OWNER=airflow
AIRFLOW_CTX_DAG_ID=TwitterDAG
AIRFLOW_CTX_TASK_ID=twitter_datascience
AIRFLOW_CTX_EXECUTION_DATE=2024-08-28T00:00:00+00:00
AIRFLOW_CTX_TRY_NUMBER=1
AIRFLOW_CTX_DAG_RUN_ID=scheduled__2024-08-28T00:00:00+00:00
[2024-08-29 00:27:31,509] {base.py:68} INFO - Using connection ID 'twitter_connections_default' for task execution.
[2024-08-29 00:27:31,510] {twitter_hook.py:34} INFO - URL: https://labdados.com/2/tweets/search/recent?query=datascience&tweet.fields=author_id,conversation_id,created_at,id,in_reply_to_user_id,public_metrics,lang,text&expansions=author_id&user.fields=id,name,username,created_at&start_time=2024-08-28T00:00:00.00Z&end_time=2024-08-29T00:00:00.00Z
[2024-08-29 00:27:32,238] {taskinstance.py:1395} INFO - Marking task as SUCCESS. dag_id=TwitterDAG, task_id=twitter_datascience, execution_date=20240828T000000, start_date=20240829T032731, end_date=20240829T032732
[2024-08-29 00:27:32,271] {local_task_job.py:156} INFO - Task exited with return code 0
[2024-08-29 00:27:32,286] {local_task_job.py:273} INFO - 0 downstream tasks scheduled from follow-on schedule check
